telegram.vendor.ptb_urllib3.urllib3.connectionpool - WARNING - Retrying (Retry(total=2, connect=None, read=None, redirect=None)) after connection broken by 'NewConnectionError('<telegram.vendor.ptb_urllib3.urllib3.connection.VerifiedHTTPSConnection object at 0x7f6948a55898>: Failed to establish a new connection: [Errno 101] Network is unreachable',)': /bot566724368:AAFbx-AjF0vPNrNCPitG2FDUNN6F436cjE0/getMe
telegram.vendor.ptb_urllib3.urllib3.connectionpool - WARNING - Retrying (Retry(total=1, connect=None, read=None, redirect=None)) after connection broken by 'NewConnectionError('<telegram.vendor.ptb_urllib3.urllib3.connection.VerifiedHTTPSConnection object at 0x7f6948a55940>: Failed to establish a new connection: [Errno 101] Network is unreachable',)': /bot566724368:AAFbx-AjF0vPNrNCPitG2FDUNN6F436cjE0/getMe
telegram.vendor.ptb_urllib3.urllib3.connectionpool - WARNING - Retrying (Retry(total=0, connect=None, read=None, redirect=None)) after connection broken by 'NewConnectionError('<telegram.vendor.ptb_urllib3.urllib3.connection.VerifiedHTTPSConnection object at 0x7f6948a559b0>: Failed to establish a new connection: [Errno 101] Network is unreachable',)': /bot566724368:AAFbx-AjF0vPNrNCPitG2FDUNN6F436cjE0/getMe
root - INFO - Бот запускается - 2020-01-14 12:45:29,235
telegram.ext.dispatcher - ERROR - No error handlers are registered, logging exception. - 2020-01-14 12:45:30,116
Traceback (most recent call last):
  File "/usr/local/lib/python3.6/site-packages/telegram/ext/dispatcher.py", line 372, in process_update
    handler.handle_update(update, self, check, context)
  File "/usr/local/lib/python3.6/site-packages/telegram/ext/handler.py", line 117, in handle_update
    return self.callback(update, context)
  File "p_bot.py", line 13, in start
    update.message.reply_text(text)
AttributeError: 'CallbackContext' object has no attribute 'message'
telegram.ext.dispatcher - ERROR - No error handlers are registered, logging exception. - 2020-01-14 12:45:32,208
Traceback (most recent call last):
  File "/usr/local/lib/python3.6/site-packages/telegram/ext/dispatcher.py", line 372, in process_update
    handler.handle_update(update, self, check, context)
  File "/usr/local/lib/python3.6/site-packages/telegram/ext/handler.py", line 117, in handle_update
    return self.callback(update, context)
  File "p_bot.py", line 13, in start
    update.message.reply_text(text)
AttributeError: 'CallbackContext' object has no attribute 'message'
telegram.ext.dispatcher - ERROR - No error handlers are registered, logging exception. - 2020-01-14 12:45:39,337
Traceback (most recent call last):
  File "/usr/local/lib/python3.6/site-packages/telegram/ext/dispatcher.py", line 372, in process_update
    handler.handle_update(update, self, check, context)
  File "/usr/local/lib/python3.6/site-packages/telegram/ext/handler.py", line 117, in handle_update
    return self.callback(update, context)
  File "p_bot.py", line 13, in start
    update.message.reply_text(text)
AttributeError: 'CallbackContext' object has no attribute 'message'
telegram.ext.dispatcher - ERROR - No error handlers are registered, logging exception. - 2020-01-14 12:45:43,870
Traceback (most recent call last):
  File "/usr/local/lib/python3.6/site-packages/telegram/ext/dispatcher.py", line 372, in process_update
    handler.handle_update(update, self, check, context)
  File "/usr/local/lib/python3.6/site-packages/telegram/ext/handler.py", line 117, in handle_update
    return self.callback(update, context)
  File "p_bot.py", line 13, in start
    update.message.reply_text(text)
AttributeError: 'CallbackContext' object has no attribute 'message'
root - INFO - Бот запускается - 2020-01-15 09:19:52,356
telegram.ext.dispatcher - ERROR - No error handlers are registered, logging exception. - 2020-01-15 09:19:53,210
Traceback (most recent call last):
  File "/usr/local/lib/python3.6/site-packages/telegram/ext/dispatcher.py", line 372, in process_update
    handler.handle_update(update, self, check, context)
  File "/usr/local/lib/python3.6/site-packages/telegram/ext/handler.py", line 117, in handle_update
    return self.callback(update, context)
  File "p_bot.py", line 13, in start
    update.message.reply_text(text)
AttributeError: 'CallbackContext' object has no attribute 'message'
telegram.ext.dispatcher - ERROR - No error handlers are registered, logging exception. - 2020-01-15 09:19:58,307
Traceback (most recent call last):
  File "/usr/local/lib/python3.6/site-packages/telegram/ext/dispatcher.py", line 372, in process_update
    handler.handle_update(update, self, check, context)
  File "/usr/local/lib/python3.6/site-packages/telegram/ext/handler.py", line 117, in handle_update
    return self.callback(update, context)
  File "p_bot.py", line 13, in start
    update.message.reply_text(text)
AttributeError: 'CallbackContext' object has no attribute 'message'
root - INFO - Бот запускается - 2020-01-15 09:25:53,801
root - INFO - Бот запускается - 2020-01-15 09:39:39,030
root - INFO - Бот запускается - 2020-01-15 09:43:22,389
root - INFO - Бот запускается - 2020-01-15 09:47:22,087
root - INFO - Бот запускается - 2020-01-15 09:48:45,682
root - INFO - Бот запускается - 2020-01-15 09:50:29,896
root - INFO - Бот запускается - 2020-01-15 09:58:16,780
root - INFO - Бот запускается - 2020-01-15 09:58:47,463
root - INFO - Бот запускается - 2020-01-15 10:01:26,017
telegram.ext.dispatcher - ERROR - No error handlers are registered, logging exception. - 2020-01-15 10:05:10,028
Traceback (most recent call last):
  File "/usr/local/lib/python3.6/site-packages/telegram/ext/dispatcher.py", line 372, in process_update
    handler.handle_update(update, self, check, context)
  File "/usr/local/lib/python3.6/site-packages/telegram/ext/handler.py", line 117, in handle_update
    return self.callback(update, context)
  File "p_bot.py", line 43, in inline_caps
    input_message_content = InputMessageContent(query.upper())
NameError: name 'InputMessageContent' is not defined
telegram.ext.dispatcher - ERROR - No error handlers are registered, logging exception. - 2020-01-15 10:05:14,005
Traceback (most recent call last):
  File "/usr/local/lib/python3.6/site-packages/telegram/ext/dispatcher.py", line 372, in process_update
    handler.handle_update(update, self, check, context)
  File "/usr/local/lib/python3.6/site-packages/telegram/ext/handler.py", line 117, in handle_update
    return self.callback(update, context)
  File "p_bot.py", line 43, in inline_caps
    input_message_content = InputMessageContent(query.upper())
NameError: name 'InputMessageContent' is not defined
telegram.ext.dispatcher - ERROR - No error handlers are registered, logging exception. - 2020-01-15 10:05:14,696
Traceback (most recent call last):
  File "/usr/local/lib/python3.6/site-packages/telegram/ext/dispatcher.py", line 372, in process_update
    handler.handle_update(update, self, check, context)
  File "/usr/local/lib/python3.6/site-packages/telegram/ext/handler.py", line 117, in handle_update
    return self.callback(update, context)
  File "p_bot.py", line 43, in inline_caps
    input_message_content = InputMessageContent(query.upper())
NameError: name 'InputMessageContent' is not defined
telegram.ext.dispatcher - ERROR - No error handlers are registered, logging exception. - 2020-01-15 10:05:42,634
Traceback (most recent call last):
  File "/usr/local/lib/python3.6/site-packages/telegram/ext/dispatcher.py", line 372, in process_update
    handler.handle_update(update, self, check, context)
  File "/usr/local/lib/python3.6/site-packages/telegram/ext/handler.py", line 117, in handle_update
    return self.callback(update, context)
  File "p_bot.py", line 43, in inline_caps
    input_message_content = InputMessageContent(query.upper())
NameError: name 'InputMessageContent' is not defined
telegram.ext.dispatcher - ERROR - No error handlers are registered, logging exception. - 2020-01-15 10:05:44,355
Traceback (most recent call last):
  File "/usr/local/lib/python3.6/site-packages/telegram/ext/dispatcher.py", line 372, in process_update
    handler.handle_update(update, self, check, context)
  File "/usr/local/lib/python3.6/site-packages/telegram/ext/handler.py", line 117, in handle_update
    return self.callback(update, context)
  File "p_bot.py", line 43, in inline_caps
    input_message_content = InputMessageContent(query.upper())
NameError: name 'InputMessageContent' is not defined
telegram.ext.dispatcher - ERROR - No error handlers are registered, logging exception. - 2020-01-15 10:05:45,286
Traceback (most recent call last):
  File "/usr/local/lib/python3.6/site-packages/telegram/ext/dispatcher.py", line 372, in process_update
    handler.handle_update(update, self, check, context)
  File "/usr/local/lib/python3.6/site-packages/telegram/ext/handler.py", line 117, in handle_update
    return self.callback(update, context)
  File "p_bot.py", line 43, in inline_caps
    input_message_content = InputMessageContent(query.upper())
NameError: name 'InputMessageContent' is not defined
telegram.ext.dispatcher - ERROR - No error handlers are registered, logging exception. - 2020-01-15 10:05:50,735
Traceback (most recent call last):
  File "/usr/local/lib/python3.6/site-packages/telegram/ext/dispatcher.py", line 372, in process_update
    handler.handle_update(update, self, check, context)
  File "/usr/local/lib/python3.6/site-packages/telegram/ext/handler.py", line 117, in handle_update
    return self.callback(update, context)
  File "p_bot.py", line 43, in inline_caps
    input_message_content = InputMessageContent(query.upper())
NameError: name 'InputMessageContent' is not defined
telegram.ext.dispatcher - ERROR - No error handlers are registered, logging exception. - 2020-01-15 10:05:51,453
Traceback (most recent call last):
  File "/usr/local/lib/python3.6/site-packages/telegram/ext/dispatcher.py", line 372, in process_update
    handler.handle_update(update, self, check, context)
  File "/usr/local/lib/python3.6/site-packages/telegram/ext/handler.py", line 117, in handle_update
    return self.callback(update, context)
  File "p_bot.py", line 43, in inline_caps
    input_message_content = InputMessageContent(query.upper())
NameError: name 'InputMessageContent' is not defined
root - INFO - Бот запускается - 2020-01-15 10:08:00,220
telegram.ext.updater - INFO - Received signal 15 (SIGTERM), stopping... - 2020-01-15 10:08:37,752
telegram.ext.updater - ERROR - Error while getting Updates: Conflict: terminated by other getUpdates request; make sure that only one bot instance is running - 2020-01-15 10:08:37,753
telegram.ext.dispatcher - ERROR - No error handlers are registered, logging exception. - 2020-01-15 10:08:37,756
Traceback (most recent call last):
  File "/usr/local/lib/python3.6/site-packages/telegram/ext/updater.py", line 332, in _network_loop_retry
    if not action_cb():
  File "/usr/local/lib/python3.6/site-packages/telegram/ext/updater.py", line 293, in polling_action_cb
    allowed_updates=allowed_updates)
  File "/usr/local/lib/python3.6/site-packages/telegram/bot.py", line 66, in decorator
    result = func(self, *args, **kwargs)
  File "/usr/local/lib/python3.6/site-packages/telegram/bot.py", line 1983, in get_updates
    result = self._request.post(url, data, timeout=float(read_latency) + float(timeout))
  File "/usr/local/lib/python3.6/site-packages/telegram/utils/request.py", line 327, in post
    **urlopen_kwargs)
  File "/usr/local/lib/python3.6/site-packages/telegram/utils/request.py", line 242, in _request_wrapper
    raise Conflict(message)
telegram.error.Conflict: Conflict: terminated by other getUpdates request; make sure that only one bot instance is running
telegram.ext.updater - INFO - Received signal 15 (SIGTERM), stopping... - 2020-01-15 10:08:37,809
telegram.ext.updater - INFO - Received signal 15 (SIGTERM), stopping... - 2020-01-15 10:08:37,868
telegram.ext.updater - INFO - Received signal 15 (SIGTERM), stopping... - 2020-01-15 10:08:37,906
telegram.ext.updater - INFO - Received signal 15 (SIGTERM), stopping... - 2020-01-15 10:08:38,099
telegram.ext.updater - INFO - Received signal 15 (SIGTERM), stopping... - 2020-01-15 10:08:38,134
telegram.ext.updater - INFO - Received signal 15 (SIGTERM), stopping... - 2020-01-15 10:08:38,707
telegram.ext.updater - ERROR - Error while getting Updates: Conflict: terminated by other getUpdates request; make sure that only one bot instance is running - 2020-01-15 10:08:41,135
telegram.ext.updater - ERROR - Error while getting Updates: Conflict: terminated by other getUpdates request; make sure that only one bot instance is running - 2020-01-15 10:08:41,135
telegram.ext.updater - ERROR - Error while getting Updates: Conflict: terminated by other getUpdates request; make sure that only one bot instance is running - 2020-01-15 10:08:41,150
telegram.ext.updater - ERROR - Error while getting Updates: Conflict: terminated by other getUpdates request; make sure that only one bot instance is running - 2020-01-15 10:08:41,154
